Workbook

Sheet Filmes
A1: ID | B1: Mostra | C1: Letterboxd | D1: Filme | E1: Título no catálogo | F1: Fonte | G1: País / território (programação) | H1: Formato (programação) | I1: Duração programada (min) | J1: Ano | K1: País | L1: Gênero (ficha) | M1: Selecionado para Festival A? | N1: Festival A | O1: Mostra / Seção | P1: Direção | Q1: Roteiro | R1: Produtora | S1: Produção | T1: Fotografia | U1: Montagem | V1: Música | W1: Elenco / participações | X1: Sinopse | Y1: Ficha técnica padronizada | Z1: Nº de sessões | AA1: Ano | AB1: Gênero padronizado
A2: 001 | B2: Panorama Mundial | C2: https://boxd.it/Rw9k | D2: A Grande Estreia | E2: Debut, The | F2: Catálogo | G2: Estados Unidos | H2: Ficção | I2: 105 | J2: 2026 | K2: Estados Unidos | L2: Ficção | P2: Jesse Eisenberg | Q2: Jesse Eisenberg | R2: Topic Studios, Fruit Tree | S2: Ali Herting, Dave Mccary, Emma Stone | T2: Drew Daniels | U2: Robert Nassau | V2: Emile Mosseri | W2: Julianne Moore, Paul Giamatti, Halle Bailey, Jesse Eisenberg, Cara Buono, Craig Bierko, Eldar Isgandarov, Bernadette Peters | X2: Quando Mona Friedman, uma dona de casa tímida e discreta, consegue um pequeno papel em um teatro comunitário, mergulha no método e se torna obcecada em defender a integridade artística de sua participação quase insignificante. Disposta a tudo, ela entra em guerra com o autoritário diretor do espetáculo. Estrelada por Julianne Moore e Paul Giamatti, esta comédia musical satiriza o ego, a ambição e os delírios da criação. Seleção do Festival de Toronto e competição oficial do Festival de San Sebastián 2026. | Y2: Direção: Jesse Eisenberg | Roteiro: Jesse Eisenberg | Produtora: Topic Studios, Fruit Tree | Produção: Ali Herting, Dave Mccary, Emma Stone | Fotografia: Drew Daniels | Montagem: Robert Nassau | Música: Emile Mosseri | Elenco: Julianne Moore, Paul Giamatti, Halle Bailey, Jesse Eisenberg, Cara Buono, Craig Bierko, Eldar Isgandarov, Bernadette Peters | Z2: 3 | AA2: 2026 | AB2: Ficção
A3: 002 | B3: Panorama Mundial | C3: https://boxd.it/Zo9i | D3: A Noiva Difícil | E3: Difficult Bride, The | F3: Catálogo | G3: França + 4 países | H3: Ficção | I3: 87 | J3: 2026 | K3: França, Portugal, Bangladesh, Noruega, Alemanha | L3: Ficção | P3: Rubaiyat Hossain | Q3: Rubaiyat Hossain | R3: Les Films de L’après-Midi | S3: François D’artemare | T3: Leonor Teles | U3: Raphaëlle Martin-Hölger | V3: Jim Williams | W3: Zaineen Chowdhury Karim, Saberi Alam Motaher, Reekita Nondine Shimu, Azmeri Haque, Sunerah Binte Kamal, Shatabdi Wadud, Dameer Khan, Mohammed Bari | X3: Em Daca, Zaineen se prepara para o próprio casamento, entre rituais de beleza e expectativas familiares. Mas seu corpo começa a reagir de maneiras inesperadas. Enquanto remédios caseiros, pressões sociais e visões perturbadoras se acumulam, o caminho até o altar se transforma em uma luta física e psicológica contra os papéis impostos às mulheres. Entre o real e o sobrenatural, ela busca a liberdade de existir para além da feminilidade prescrita. Seleção da mostra Orizzonti do Festival de Veneza 2026. | Y3: Direção: Rubaiyat Hossain | Roteiro: Rubaiyat Hossain | Produtora: Les Films de L’après-Midi | Produção: François D’artemare | Fotografia: Leonor Teles | Montagem: Raphaëlle Martin-Hölger | Música: Jim Williams | Elenco: Zaineen Chowdhury Karim, Saberi Alam Motaher, Reekita Nondine Shimu, Azmeri Haque, Sunerah Binte Kamal, Shatabdi Wadud, Dameer Khan, Mohammed Bari | Z3: 3 | AA3: 2026 | AB3: Ficção
A4: 003 | B4: Panorama Mundial | C4: https://boxd.it/W19e | D4: A Terceira Noite | E4: Troisième nuit, La | F4: Catálogo | G4: França | H4: Ficção | I4: 90 | J4: 2026 | K4: França | L4: Ficção | M4: Sim | N4: Cannes | O4: Cannes Première | P4: Daniel Auteuil | Q4: Daniel Auteuil, Camille Lugan | R4: Palatio Films, Les Films Velvet | S4: Frédéric Jouve, Adrien Nussembaum, Nelly Auteuil | T4: Jean-François Hensgens | U4: Valérie Deseine | V4: Oliver Goinard | W4: Antonie Reinartz, Daniel Auteuil, Luàna Bjarami, Grégory Gadebois, Grégoire Colin, Yannick Choirat, Jean- Paul Muel | X4: Em agosto de 1942, na França ocupada, o governo de Vichy organiza a deportação em massa de judeus estrangeiros. Um jovem funcionário público encarregado da triagem e um padre humanitário unem forças secretas para desafiar a burocracia do Estado. Juntos, arriscam tudo em uma missão desesperada para salvar mais de cem crianças judias de um campo perto de Lyon. | Y4: Direção: Daniel Auteuil | Roteiro: Daniel Auteuil, Camille Lugan | Produtora: Palatio Films, Les Films Velvet | Produção: Frédéric Jouve, Adrien Nussembaum, Nelly Auteuil | Fotografia: Jean-François Hensgens | Montagem: Valérie Deseine | Música: Oliver Goinard | Elenco: Antonie Reinartz, Daniel Auteuil, Luàna Bjarami, Grégory Gadebois, Grégoire Colin, Yannick Choirat, Jean- Paul Muel | Z4: 3 | AA4: 2026 | AB4: Ficção
A5: 004 | B5: Panorama Mundial | C5: https://boxd.it/VBPy | D5: Amazomania | F5: Complementar / catálogo parcial | G5: Suécia + 2 países | H5: Documentário | I5: 95 | J5: 2026 | K5: Dinamarca, França, Suécia | L5: Documentário | P5: Nathan Grossman | R5: B-Reel Films | S5: Cecilia Nessen | T5: Nathan Grossman, Erling Söderström, Diego Lajst | U5: Jordana Berg, Nathan Grossman | V5: Nicole Hogstrand, Thora Kidon Jæger | W5: Barbara Arisi, Binan Tuku, Comunidade Korubo, Erling Söderström, Malevo, Seatvo, Sydney Possuelo, Takvan, Takvan Vakwë, Xikxuvo | X5: Em 1996, um servidor público brasileiro e um jornalista sueco entraram na Amazônia para documentar o primeiro contato com o povo Korubo, até então completamente isolado. Quase três décadas depois, as imagens ressurgem sob uma perspectiva inquietante. Ao refazer sua jornada e voltar ao Brasil após décadas, o jornalista encontra os Korubo exigindo reparação e o direito de contar a própria história. O resultado confronta o olhar colonial, os mal-entendidos culturais, o empoderamento dos povos indígenas e a própria ética do documentário. Prêmio FIPRESCI no CPH:DOX 2026. | Y5: Direção: Nathan Grossman | Produtora: B-Reel Films | Produção: Cecilia Nessen | Fotografia: Nathan Grossman, Erling Söderström, Diego Lajst | Montagem: Jordana Berg, Nathan Grossman | Música: Nicole Hogstrand, Thora Kidon Jæger | Elenco: Barbara Arisi, Binan Tuku, Comunidade Korubo, Erling Söderström, Malevo, Seatvo, Sydney Possuelo, Takvan, Takvan Vakwë, Xikxuvo | Z5: 2 | AA5: 2026 | AB5: Documentário
A6: 005 | B6: Panorama Mundial | C6: https://boxd.it/MK5w | D6: As Crianças Estão Bem | E6: Enfants Vont Bien, Les | F6: Catálogo | G6: França | H6: Ficção | I6: 111 | J6: 2025 | K6: França | L6: Ficção | P6: Nathan Ambrosioni | Q6: Nathan Ambrosioni | R6: Chi-Fou-Mi Productions | S6: Nicolas Dumont, Hugo Selignac | T6: Victor Seguin - Afc | U6: Nathan Ambrosioni, Alexandre Hecker, Laure-Anne Darras, Olivier Guillaume | V6: Alexandre de la Baume | W6: Camille Cottin, Monia Chokri, Juliette Armanet, Manoã Varvat, Nina Birman, Guillaume Gouix, Myriem Akheddiou, Franckie Wallach, Tania Dessources, Camille Lethuillier, Maxime Tshibangu, Féodor Atkine | X6: Numa noite de verão, Suzanne visita a irmã Jeanne e deixa com ela os dois filhos pequenos. Na manhã seguinte, Suzanne desaparece sem deixar rastros, exceto por uma carta pedindo que não a procurem. Jeanne vê-se subitamente forçada a assumir o papel de mãe biológica e a cuidar dos sobrinhos diante de um abandono voluntário. Enquanto a família tenta digerir o trauma e a ausência enigmática da mãe, o drama foca na perda da inocência e na resiliência das crianças. Em competição no Festival de Cannes 2026. | Y6: Direção: Nathan Ambrosioni | Roteiro: Nathan Ambrosioni | Produtora: Chi-Fou-Mi Productions | Produção: Nicolas Dumont, Hugo Selignac | Fotografia: Victor Seguin - Afc | Montagem: Nathan Ambrosioni, Alexandre Hecker, Laure-Anne Darras, Olivier Guillaume | Música: Alexandre de la Baume | Elenco: Camille Cottin, Monia Chokri, Juliette Armanet, Manoã Varvat, Nina Birman, Guillaume Gouix, Myriem Akheddiou, Franckie Wallach, Tania Dessources, Camille Lethuillier, Maxime Tshibangu, Féodor Atkine | Z6: 5 | AA6: 2025 | AB6: Ficção
A7: 006 | B7: Panorama Mundial | C7: https://boxd.it/ST8Q | D7: Bucking Fastard | F7: Complementar / catálogo parcial | G7: Estados Unidos | H7: Ficção | I7: 109 | J7: 2026 | K7: Estados Unidos | L7: Ficção | M7: Sim | N7: Veneza | O7: Venezia 83 – Competição | P7: Werner Herzog | Q7: Werner Herzog | R7: Gateway To Orkney, Providence Road Entertainment | S7: Clara Wu Tsai, Werner Herzog, Ariel Leon Isacovitch | T7: Peter Zeitlinger | U7: Marco Capalbo | V7: Ernst Reijseger | W7: Kate Mara, Rooney Mara, Orlando Bloom, Domhnall Gleeson | X7: Jean e Joan Holbrooke são irmãs tão inseparáveis que falam em uníssono, compartilham os mesmos sonhos e amam o mesmo homem. Em busca de uma terra imaginária onde o amor verdadeiro seja possível, decidem escavar um túnel através de uma cadeia de montanhas. Livremente inspirado nas gêmeas britânicas Freda e Greta Chaplin, Werner Herzog transforma sua obstinação numa fábula sobre amor, marginalidade e sonhos impossíveis. Com Kate e Rooney Mara. Selecionado para a competição do Festival de Veneza de 2026. | Y7: Direção: Werner Herzog | Roteiro: Werner Herzog | Produtora: Gateway To Orkney, Providence Road Entertainment | Produção: Clara Wu Tsai, Werner Herzog, Ariel Leon Isacovitch | Fotografia: Peter Zeitlinger | Montagem: Marco Capalbo | Música: Ernst Reijseger | Elenco: Kate Mara, Rooney Mara, Orlando Bloom, Domhnall Gleeson | Z7: 3 | AA7: 2026 | AB7: Ficção
A8: 007 | B8: Panorama Mundial | C8: https://boxd.it/Odiw | D8: Cartas Amarelas | E8: Gelbe Briefe | F8: Catálogo | G8: Alemanha + 2 países | H8: Ficção | I8: 127 | J8: 2026 | K8: França, Alemanha, Turquia | L8: Ficção | M8: Sim | N8: Berlinale | O8: Competição Oficial | P8: Ilker Çatak | Q8: Ayda Meryem Çatak, Enis Köstepen | R8: Liman Film, If... Productions, Haut Et Court | S8: Ingo Fliess | T8: Judith Kaufmann | U8: Gesa Jäger | V8: Marvin Miller | W8: Yusuf Akgün, Aydin Işik, Aziz Çapkurt, Elit İşcan, Emine Meyrem, Emre Bakar, Ipek Seyalioglu, Jale Arikan, Leyla Smyrna Cabas, Seda Türkmen, Sultan Ulutaş, Tansu Biçer, Uygar Tamer, Yusuf Özhan Tali, Özgü Namal, İpek Bilgin | X8: Em Ancara, Derya e Aziz formam um respeitado casal de artistas: ela é atriz, ele é dramaturgo e professor. Durante a estreia de uma nova peça, um gesto de desobediência os coloca sob investigação do Estado. Em poucos dias, perdem o trabalho e a casa e precisam se mudar com a filha adolescente para Istambul. À medida que o dinheiro escasseia e a pressão autoritária invade a vida doméstica, suas convicções, o casamento e o futuro da família são postos à prova. Urso de Ouro no Festival de Berlim 2026. | Y8: Direção: Ilker Çatak | Roteiro: Ayda Meryem Çatak, Enis Köstepen | Produtora: Liman Film, If... Productions, Haut Et Court | Produção: Ingo Fliess | Fotografia: Judith Kaufmann | Montagem: Gesa Jäger | Música: Marvin Miller | Elenco: Yusuf Akgün, Aydin Işik, Aziz Çapkurt, Elit İşcan, Emine Meyrem, Emre Bakar, Ipek Seyalioglu, Jale Arikan, Leyla Smyrna Cabas, Seda Türkmen, Sultan Ulutaş, Tansu Biçer, Uygar Tamer, Yusuf Özhan Tali, Özgü Namal, İpek Bilgin | Z8: 3 | AA8: 2026 | AB8: Ficção
A9: 008 | B9: Panorama Mundial | C9: https://boxd.it/xG0M | D9: Cavalo Selvagem Nove | E9: Wild Horse Nine | F9: Catálogo | G9: Reino Unido + 1 país | H9: Ficção | I9: 116 | J9: 2026 | K9: Estados Unidos, Reino Unido | L9: Ficção | M9: Sim | N9: Veneza | O9: Venezia 83 – Competição | P9: Martin Mcdonagh | Q9: Martin Mcdonagh | R9: Searchlight Pictures, Blueprint Pictures, Film4 | S9: Graham Broadbent, Pete Czernin, Martin Mcdonagh, Anita Overland | T9: Ben Davis, Bsc | U9: Mikkel e G Nielsen, Ace | V9: Carter Burwell | W9: John Malkovich, Sam Rockwell, Steve Buscemi, Mariana di Girolamo, Ailín Salas, Tom Waits, Parker Posey | X9: Pouco antes do golpe de Estado no Chile em 1973, dois agentes da CIA são enviados de Santiago para a Ilha de Páscoa em uma missão de teste de confiança. Entre as famosas estátuas que são o marco da ilha, conhecidas como muais, eles enfrentam passados sombrios e conspirações, enquanto o envolvimento de um dos agentes com estudantes rebeldes ameaça arruinar a viagem. Uma afiada combinação de thriller político, drama existencial e comédia sombria. | Y9: Direção: Martin Mcdonagh | Roteiro: Martin Mcdonagh | Produtora: Searchlight Pictures, Blueprint Pictures, Film4 | Produção: Graham Broadbent, Pete Czernin, Martin Mcdonagh, Anita Overland | Fotografia: Ben Davis, Bsc | Montagem: Mikkel e G Nielsen, Ace | Música: Carter Burwell | Elenco: John Malkovich, Sam Rockwell, Steve Buscemi, Mariana di Girolamo, Ailín Salas, Tom Waits, Parker Posey | Z9: 5 | AA9: 2026 | AB9: Ficção
A10: 009 | B10: Panorama Mundial | C10: https://boxd.it/15fbc | D10: Cidadão Osama | E10: Al mowaten Osama | F10: Catálogo | G10: Palestina + 2 países | H10: Documentário | I10: 69 | J10: 2026 | K10: Palestina, França, Catar | L10: Documentário | P10: Ahmed Hassouna | R10: Filcam Media For Media Production, Masharawi Fund For Films & Filmmakers, Coorigines Production | S10: Laura Nikolov, Rashid Masharawi, Ahmed Hassouna | T10: Ahmed Hassouna | U10: DENIS LE PAVEN Edição de Som e Mixagem /Sound Editing and Mixing: HATEM SALMI | V10: Rasmus Steen, Sarah Fasseur-Leroux | W10: Osama Al-Ashi | X10: No norte da Faixa de Gaza sob cerco, Osama, ex-fotógrafo artístico que se tornou documentarista de guerra, tenta proteger a esposa e o filho recém-nascido enquanto registra a devastação ao seu redor. Entre bombardeios, fome e perdas, divide-se entre o dever de testemunhar e as urgências da paternidade. Filmado em meio à guerra, o documentário acompanha um homem que mostra a tragédia ao mundo enquanto também a vive. Estreia mundial no Venice Open do Festival de Veneza de 2026. | Y10: Direção: Ahmed Hassouna | Produtora: Filcam Media For Media Production, Masharawi Fund For Films & Filmmakers, Coorigines Production | Produção: Laura Nikolov, Rashid Masharawi, Ahmed Hassouna | Fotografia: Ahmed Hassouna | Montagem: DENIS LE PAVEN Edição de Som e Mixagem /Sound Editing and Mixing: HATEM SALMI | Música: Rasmus Steen, Sarah Fasseur-Leroux | Elenco: Osama Al-Ashi | Z10: 3 | AA10: 2026 | AB10: Documentário
A11: 010 | B11: Panorama Mundial | C11: https://boxd.it/HOdk | D11: Contos Paralelos | E11: Histoires parallèles | F11: Catálogo | G11: França | H11: Ficção | I11: 141 | J11: 2026 | K11: França | L11: Ficção | M11: Sim | N11: Cannes | O11: Competição Oficial | P11: Asghar Farhadi | Q11: Asghar Farhadi, Saeed Farhadi, Krzysztof Kieslowski | R11: Anonymous Content, Memento Production | S11: Alexandre Mallet-Guy, Asghar Farhadi, David Levine | T11: Guillaume Deffontaines | U11: Hayedeh Safiyari | V11: Zbigniew Preisner | W11: Isabelle Huppert, Virginie Efira, Vincent Cassel, Adam Bessa, Pierre Niney, India Hair, Catherine Deneuve | X11: Em busca de inspiração para o seu novo romance, Sylvie, uma famosa escritora reclusa em Paris, passa os dias a espionar a vida dos vizinhos do prédio da frente com uma luneta. Decidida a movimentar a rotina, ela contrata o enigmático jovem Adam como seu assistente de escrita. Ela só não imaginava que a presença dele viraria o seu mundo e o seu trabalho de cabeça para baixo, até chegar ao ponto em que a ficção imaginada por ela passa a superar a própria realidade de todos. O filme foi exibido na mostra competitiva do Festival de Cannes 2026. | Y11: Direção: Asghar Farhadi | Roteiro: Asghar Farhadi, Saeed Farhadi, Krzysztof Kieslowski | Produtora: Anonymous Content, Memento Production | Produção: Alexandre Mallet-Guy, Asghar Farhadi, David Levine | Fotografia: Guillaume Deffontaines | Montagem: Hayedeh Safiyari | Música: Zbigniew Preisner | Elenco: Isabelle Huppert, Virginie Efira, Vincent Cassel, Adam Bessa, Pierre Niney, India Hair, Catherine Deneuve | Z11: 4 | AA11: 2026 | AB11: Ficção
A12: 011 | B12: Panorama Mundial | C12: https://boxd.it/15fds | D12: Conversa com o Mar | E12: Hiwar ma’ albahr | F12: Catálogo | G12: Catar + 1 país | H12: Ficção | I12: 110 | J12: 2026 | K12: Catar, Palestina | L12: Ficção | P12: Muayad Alayan | Q12: Rami Alayan | R12: Palcine Productions | S12: Muayad Alayan, Rami Alayan | T12: Lorenzo Casadio Vannucci | U12: Matteo Faccenda | V12: Fabienne van Eck | W12: Kamel El Basha, Amer Hlehel , Bahira Ablassi, Maria Zreik, Ebla Mari, Rebecca Esmeralda Telhami | X12: Em Jerusalém, Kamal, um palestino de 60 anos, recebe uma ordem judicial israelense para pagar uma dívida previdenciária em nome do filho Wael, que teria morrido afogado no Mar Vermelho duas décadas antes. Quando descobre que não há registro oficial de sua morte, Kamal parte em busca da verdade sobre o destino do filho, confrontando uma ferida do passado que jamais cicatrizou. | Y12: Direção: Muayad Alayan | Roteiro: Rami Alayan | Produtora: Palcine Productions | Produção: Muayad Alayan, Rami Alayan | Fotografia: Lorenzo Casadio Vannucci | Montagem: Matteo Faccenda | Música: Fabienne van Eck | Elenco: Kamel El Basha, Amer Hlehel , Bahira Ablassi, Maria Zreik, Ebla Mari, Rebecca Esmeralda Telhami | Z12: 3 | AA12: 2026 | AB12: Ficção
A13: 012 | B13: Panorama Mundial | C13: https://boxd.it/TcSy | D13: Covarde | E13: Coward | F13: Catálogo | G13: Bélgica + 2 países | H13: Ficção | I13: 100 | J13: 2026 | K13: Bélgica, França, Países Baixos | L13: Ficção | M13: Sim | N13: Cannes | O13: Competição Oficial | P13: Lukas Dhont | Q13: Lucas Dhont, Angelo Tijssens | R13: The Reunion, Versus Productions, Lumen, Topkapi Films | S13: Michiel Dhont | T13: Frank van Den Eeden | U13: Alain Dessauvage | V13: Valentin Hadjadj | W13: Emannuel Macchia, Valentin Campagne, Jef Jacobs, Willen de Schryver, Liam Jacqmin, Mistral Guigot, Jonas Wertz | X13: Em 1916, em plena Primeira Guerra Mundial, o jovem soldado belga Pierre é enviado para o brutal fronte de batalha das trincheiras. Para tentar manter a sanidade, ele decide juntar-se a uma trupe de teatro improvisada nos bastidores da linha inimiga. Lá, Pierre conhece Francis, o líder criativo do grupo, e os dois acabam desenvolvendo uma intensa e secreta história de amor. Prêmio de Melhor Ator em Cannes 2026, dividido ex aequo entre os dois protagonistas, Emmanuel Macchia e Valentin Campagne. | Y13: Direção: Lukas Dhont | Roteiro: Lucas Dhont, Angelo Tijssens | Produtora: The Reunion, Versus Productions, Lumen, Topkapi Films | Produção: Michiel Dhont | Fotografia: Frank van Den Eeden | Montagem: Alain Dessauvage | Música: Valentin Hadjadj | Elenco: Emannuel Macchia, Valentin Campagne, Jef Jacobs, Willen de Schryver, Liam Jacqmin, Mistral Guigot, Jonas Wertz | Z13: 3 | AA13: 2026 | AB13: Ficção
A14: 013 | B14: Panorama Mundial | C14: https://boxd.it/13fZW | D14: Crianças Invisíveis | E14: Watashi no Shiranai Kodomotachi | F14: Catálogo | G14: Japão | H14: Ficção | I14: 150 | J14: 2026 | K14: Japão | L14: Ficção | P14: Miwa Nishikawa | Q14: Miwa Nishikawa | R14: K2 Pictures, Aoi Pro. | S14: Daiju Koide, Taichi Ito | T14: Norimichi Kasamatsu | U14: Tomomi Kikuchi | V14: Marihiko Hara | W14: Ami Koyae, Fumi Nikaido, Yutaka Takenouchi, Kaito Sakurai | X14: Nos dias finais da Segunda Guerra em Tóquio, uma órfã de 12 anos, filha de músicos, disfarça-se de menino para sobreviver ao submundo. Enquanto isso, sua antiga professora, tomada pela culpa e pela própria luta pela sobrevivência, refaz seus passos em uma busca desesperada. Um drama histórico tocante sobre as marcas invisíveis do conflito. Baseado em fatos reais, o filme abriu a mostra Platform no Festival de Toronto 2026. | Y14: Direção: Miwa Nishikawa | Roteiro: Miwa Nishikawa | Produtora: K2 Pictures, Aoi Pro. | Produção: Daiju Koide, Taichi Ito | Fotografia: Norimichi Kasamatsu | Montagem: Tomomi Kikuchi | Música: Marihiko Hara | Elenco: Ami Koyae, Fumi Nikaido, Yutaka Takenouchi, Kaito Sakurai | Z14: 3 | AA14: 2026 | AB14: Ficção
A15: 014 | B15: Panorama Mundial | C15: https://boxd.it/159U6 | D15: Dau | E15: Dau | F15: Complementar / catálogo parcial | G15: Alemanha + 2 países | H15: Ficção | I15: 217 | J15: 2026 | K15: Alemanha, França, Suécia | L15: Documentário | M15: Sim | N15: Veneza | O15: Venezia 83 – Competição | P15: Ilya Khrzhanovsky | Q15: Ilya Khrzhanovsky, Susanne Marian, Vladimir Sorokin, Ilia Permyakov | R15: Phenomen Berlin | S15: Ilya Khrzhanovsky, Svetlana Dragayeva, Philippe Bober, Solal Coutard, Susanne Marian, Erik Hemmendorff | T15: Jürgen Jürges, Manuel Alberto Claro, Lol Crawley | U15: Ilya Permyakov, Rob Myers | W15: Teodor Currentzis, Radmila Shchogolieva, Anatoly Vasiliev | X15: Na União Soviética, Dau é um físico brilhante movido pelo desejo de compreender as leis do universo. Recrutado para trabalhar em um instituto secreto, vê sua pesquisa colocada a serviço da criação da bomba atômica. Entre a vigilância do Estado, os privilégios da vida no instituto e uma sucessão de relações amorosas, suas convicções cedem aos poucos. Acompanhando quatro décadas de sua vida, o filme observa como escolhas íntimas e concessões cotidianas se entrelaçam à história de um regime. Projeto de uma década e prêmio de melhor Direção no Festival de Veneza de 2026. | Y15: Direção: Ilya Khrzhanovsky | Roteiro: Ilya Khrzhanovsky, Susanne Marian, Vladimir Sorokin, Ilia Permyakov | Produtora: Phenomen Berlin | Produção: Ilya Khrzhanovsky, Svetlana Dragayeva, Philippe Bober, Solal Coutard, Susanne Marian, Erik Hemmendorff | Fotografia: Jürgen Jürges, Manuel Alberto Claro, Lol Crawley | Montagem: Ilya Permyakov, Rob Myers | Elenco: Teodor Currentzis, Radmila Shchogolieva, Anatoly Vasiliev | Z15: 3 | AA15: 2026 | AB15: Documentário
A16: 015 | B16: Panorama Mundial | C16: https://boxd.it/TCSY | D16: Diários de Nagi | E16: Nagi daiarî | F16: Catálogo | G16: Japão + 3 países | H16: Ficção | I16: 110 | J16: 2026 | K16: Japão, França, Singapura, Filipinas | L16: Ficção | M16: Sim | N16: Cannes | O16: Competição Oficial | P16: Koji Fukada | Q16: Koji Fukada | R16: Survivance, Star Sands | S16: Atsuko Ohno, Ryo Nagai, Michiaki Tsunoda | T16: Hidetoshi Shinomiya | U16: Sylvie Lager | V16: Lee Pei-Chin | W16: Takako Matsu, Shizuka Ishibashi, Ken’ichi Matsuyama, Waku Kawaguchi, Kiyora Fujiwara, Sawako Fujima, Long Mizuma, Suhkye Shin | X16: Na pequena cidade rural de Nagi, Yoriko divide seus dias entre o trabalho no campo e a escultura, enquanto tenta conviver com as marcas de um amor do passado. Sua rotina é interrompida pela chegada de Yuri, sua amiga e ex-cunhada, uma arquiteta que deixa Tóquio após o fim do casamento. Yuri vai posar para uma escultura de Yoriko, e ao longo dos dias, nesse processo, elas se reaproximam e encontram, uma na outra, novas formas de lidar com a perda, a solidão e os caminhos que acabaram por não seguir na vida. Exibido na Competição Oficial do Festival de Cannes 2026. | Y16: Direção: Koji Fukada | Roteiro: Koji Fukada | Produtora: Survivance, Star Sands | Produção: Atsuko Ohno, Ryo Nagai, Michiaki Tsunoda | Fotografia: Hidetoshi Shinomiya | Montagem: Sylvie Lager | Música: Lee Pei-Chin | Elenco: Takako Matsu, Shizuka Ishibashi, Ken’ichi Matsuyama, Waku Kawaguchi, Kiyora Fujiwara, Sawako Fujima, Long Mizuma, Suhkye Shin | Z16: 3 | AA16: 2026 | AB16: Ficção
A17: 016 | B17: Panorama Mundial | C17: https://boxd.it/Og8k | D17: Eu Juro | E17: I Swear | F17: Catálogo | G17: Reino Unido | H17: Ficção | I17: 120 | J17: 2025 | K17: Reino Unido | L17: Ficção | P17: Kirk Jones | Q17: Kirk Jones | R17: Tempo Productions, One Story High | S17: Georgia Bayliff, Kirk Jones, Piers Tempest | T17: James Blann | U17: Sam Sneade | V17: Stephen Rennicks | W17: Robert Aramayo, Maxine Peake, Peter Mullan, Sanjeev Kohli, Shirley Henderson | X17: Escócia, anos 1980. Quando o adolescente John Davidson começa a manifestar tiques e explosões verbais involuntárias, pouco se sabia ainda sobre a síndrome de Tourette. Incompreendido pela família, pela escola e pela comunidade, ele enfrenta preconceito e isolamento. O apoio inesperado de pessoas dispostas a enxergá-lo para além de sua condição o ajuda a transformar a própria experiência em uma luta por reconhecimento. Inspirado em uma história real. | Y17: Direção: Kirk Jones | Roteiro: Kirk Jones | Produtora: Tempo Productions, One Story High | Produção: Georgia Bayliff, Kirk Jones, Piers Tempest | Fotografia: James Blann | Montagem: Sam Sneade | Música: Stephen Rennicks | Elenco: Robert Aramayo, Maxine Peake, Peter Mullan, Sanjeev Kohli, Shirley Henderson | Z17: 3 | AA17: 2025 | AB17: Ficção
A18: 017 | B18: Panorama Mundial | C18: https://boxd.it/DYn2 | D18: Euforia | E18: Euphoria | F18: Catálogo | G18: Alemanha + 3 países | H18: Documentário | I18: 91 | J18: 2026 | K18: Alemanha, Bulgária, Estados Unidos, Ucrânia | L18: Documentário | P18: Julian Rosefeldt | Q18: Julian Rosefeldt | R18: Park Avenue Armory New York | S18: Julian Rosefeldt | T18: Christoph Krauss | U18: Bobby Good | V18: Samy Moussa | W18: Giancarlo Esposito, Virginia Newcomb, Jeff Wood, Tim Williams, Eric Hansen, Jeff Burrell, Robert Bronzi, Kate Strong, Ayesha Jordan, Dora Zygouri, Esther Odumade, Tia Murrell, Asa Ali, Luis Rosefeldt, Rocio Rodriguez-Inniss | X18: Em uma Nova York distópica à beira do colapso, personagens e animais surreais conduzem uma viagem hipnótica pelo capitalismo e pela ganância humana. Realizado ao longo de seis anos, reunindo dois mil anos de ideias, de Platão e Karl Marx a bell hooks, Snoop Dogg e Cardi B, este filme visualmente arrebatador questiona por que um sistema econômico reconhecidamente destrutivo continua tão sedutor e aparentemente sem alternativa. Com Giancarlo Esposito e a voz de Cate Blanchett. | Y18: Direção: Julian Rosefeldt | Roteiro: Julian Rosefeldt | Produtora: Park Avenue Armory New York | Produção: Julian Rosefeldt | Fotografia: Christoph Krauss | Montagem: Bobby Good | Música: Samy Moussa | Elenco: Giancarlo Esposito, Virginia Newcomb, Jeff Wood, Tim Williams, Eric Hansen, Jeff Burrell, Robert Bronzi, Kate Strong, Ayesha Jordan, Dora Zygouri, Esther Odumade, Tia Murrell, Asa Ali, Luis Rosefeldt, Rocio Rodriguez-Inniss | Z18: 3 | AA18: 2026 | AB18: Documentário
A19: 018 | B19: Panorama Mundial | C19: https://boxd.it/Nyto | D19: Histórias de Família | E19: Etwas ganz Besonderes | F19: Catálogo | G19: Alemanha | H19: Ficção | I19: 116 | J19: 2026 | K19: Alemanha | L19: Ficção | P19: Eva Trobisch | Q19: Eva Trobisch | R19: Trimafilm | S19: Trini Götze, David Armati Lechner | T19: Adrian Campean | U19: Laura Lauzemis | V19: Teho Teardo | W19: Frida Hornemann, Max Riemelt, Eva Löbau, Rahel Ohm, Peter René Lüdicke, Gina Henkel | X19: Lea tem 16 anos, pais recém-divorciados e talento para cantar. Durante a seleção para participar de um reality show musical, a equipe pergunta quem ela é e o que a torna especial. Sem encontrar resposta, a adolescente passa a experimentar diferentes versões de si mesma e se aproxima da tia Kati, que retorna à cidade após anos no exterior. Nas florestas da antiga Alemanha Oriental, enquanto os avós tentam salvar o hotel da família da falência, três gerações confrontam suas histórias, tensões e desejos de partir. Exibido na competição oficial do Festival de Berlim 2026. | Y19: Direção: Eva Trobisch | Roteiro: Eva Trobisch | Produtora: Trimafilm | Produção: Trini Götze, David Armati Lechner | Fotografia: Adrian Campean | Montagem: Laura Lauzemis | Música: Teho Teardo | Elenco: Frida Hornemann, Max Riemelt, Eva Löbau, Rahel Ohm, Peter René Lüdicke, Gina Henkel | Z19: 3 | AA19: 2026 | AB19: Ficção
A20: 019 | B20: Panorama Mundial | C20: https://boxd.it/Jd66 | D20: Histórias Noturnas | E20: Histoires De La Nuit | F20: Catálogo | G20: França | H20: Ficção | I20: 114 | J20: 2026 | K20: França | L20: Ficção | P20: Léa Mysius | Q20: Léa Mysius | R20: Beside Productions, Division, F Comme Film, France 3 Cinéma | S20: Marie-Ange Luciani, Jean-Louis Livi | T20: Paul Guilhaume | U20: Yorgos Lamprinos | V20: Florencia di Concilio | W20: Hafsia Herzi, Benoît Magimel, Bastien Bouillon, Monica Bellucci, Tawba El Gharchi, Paul Hamy, Alane Delhaye, Servane Ducorps, Tatia Tsuladze, Jean-Paul Daniel, Dario Hardouin Spurio | X20: Nora, Thomas e a filha adolescente vivem isolados em uma fazenda no interior, tendo como única vizinha uma pintora italiana. Enquanto organizam uma festa surpresa de aniversário para Nora, a tranquilidade do lugar é quebrada. Três homens misteriosos surgem e invadem a comemoração, trazendo à tona segredos perigosos e bem guardados do passado. Um thriller rural claustrofóbico e tenso sobre uma noite de terror, invasão e revelações familiares violentas. | Y20: Direção: Léa Mysius | Roteiro: Léa Mysius | Produtora: Beside Productions, Division, F Comme Film, France 3 Cinéma | Produção: Marie-Ange Luciani, Jean-Louis Livi | Fotografia: Paul Guilhaume | Montagem: Yorgos Lamprinos | Música: Florencia di Concilio | Elenco: Hafsia Herzi, Benoît Magimel, Bastien Bouillon, Monica Bellucci, Tawba El Gharchi, Paul Hamy, Alane Delhaye, Servane Ducorps, Tatia Tsuladze, Jean-Paul Daniel, Dario Hardouin Spurio | Z20: 3 | AA20: 2026 | AB20: Ficção
A21: 020 | B21: Panorama Mundial | C21: https://boxd.it/N8by | D21: I want your sex | E21: want your sex, I | F21: Catálogo | G21: Estados Unidos | H21: Ficção | I21: 90 | J21: 2026 | K21: Estados Unidos | L21: Ficção | M21: Sim | N21: Sundance | O21: Premieres | P21: Gregg Araki | Q21: Karley Sciortino, Gregg Araki | R21: Desperate Pictures, Black Bear Pictures | S21: Gregg Araki, Seth Caplan, Teddy Schwarzman, Michael Heimler, Courtney L. Cunniff, , Karley Sciortino | T21: Tucker Korte | U21: Gregg Araki, Victor de la Parra | V21: James Clements | W21: Olivia Wilde, Cooper Hoffman, Mason Gooding, Chase Sui Wonders, Johnny Knoxville, Margaret Cho, Roxane Mesquida | X21: Quando o jovem Elliot consegue um emprego com Erika Tracy, artista célebre, provocadora e imprevisível, suas fantasias parecem se tornar realidade. Escolhido por ela como objeto de inspiração e parceiro sexual, ele é arrastado para uma relação marcada pelo desejo e por jogos de poder. Mas o que começa como uma aventura libertadora logo conduz Elliot a um universo de obsessão, traição e assassinato. Estreia mundial na seção Premieres do Festival de Sundance de 2026. | Y21: Direção: Gregg Araki | Roteiro: Karley Sciortino, Gregg Araki | Produtora: Desperate Pictures, Black Bear Pictures | Produção: Gregg Araki, Seth Caplan, Teddy Schwarzman, Michael Heimler, Courtney L. Cunniff, , Karley Sciortino | Fotografia: Tucker Korte | Montagem: Gregg Araki, Victor de la Parra | Música: James Clements | Elenco: Olivia Wilde, Cooper Hoffman, Mason Gooding, Chase Sui Wonders, Johnny Knoxville, Margaret Cho, Roxane Mesquida | Z21: 3 | AA21: 2026 | AB21: Ficção
A22: 021 | B22: Panorama Mundial | C22: https://boxd.it/X3MY | D22: Ink | F22: Complementar / catálogo parcial | G22: Reino Unido | H22: Ficção | I22: 116 | J22: 2026 | K22: Reino Unido | L22: Ficção | M22: Sim | N22: Veneza | O22: Venezia 83 – Competição | P22: Danny Boyle | Q22: James Graham | R22: Studiocanal, Media Res, House Productions | S22: Anna Marsh, Ron Halpern, Joe Naftalin, Tessa Ross, Michael Ellenberg | T22: Alwin Küchler, Bsc | U22: Fin Oates | V22: Daniel Pemberton | W22: Jack O’connell, Guy Pearce, Claire Foy, Blake Harrison, Patrick Kennedy, Brian Gleeson, Bertie Carvel, Christopher Fulford, Jonathan Hyde | X22: Londres, 1969. Rupert Murdoch compra o decadente jornal The Sun e entrega ao editor Larry Lamb uma missão aparentemente impossível: tirar do Daily Mirror o posto de jornal mais vendido do país. À frente de uma equipe disposta a romper convenções, Lamb reinventa a linguagem do jornal para conquistar o público. Em meio a manchetes provocadoras e uma disputa feroz por leitores, nasce um novo modelo de imprensa, cujos efeitos se fariam sentir muito além das bancas. Adaptação da peça de James Graham. Filme de abertura do Festival de Veneza 2026. | Y22: Direção: Danny Boyle | Roteiro: James Graham | Produtora: Studiocanal, Media Res, House Productions | Produção: Anna Marsh, Ron Halpern, Joe Naftalin, Tessa Ross, Michael Ellenberg | Fotografia: Alwin Küchler, Bsc | Montagem: Fin Oates | Música: Daniel Pemberton | Elenco: Jack O’connell, Guy Pearce, Claire Foy, Blake Harrison, Patrick Kennedy, Brian Gleeson, Bertie Carvel, Christopher Fulford, Jonathan Hyde | Z22: 3 | AA22: 2026 | AB22: Ficção
A23: 022 | B23: Panorama Mundial | C23: https://boxd.it/NzPA | D23: Josephine - Fragmentos de um Crime | E23: Josephine | F23: Catálogo | G23: Estados Unidos | H23: Ficção | I23: 119 | J23: 2026 | K23: Estados Unidos | L23: Ficção | M23: Sim | N23: Sundance; Berlinale | O23: U.S. Dramatic Competition; Competição Oficial | P23: Beth de Araújo | Q23: Beth de Araújo | R23: Kaplan Morrison, Yintai Entertainment, Free Association, Spark Features | S23: David Kaplan, Josh Peters, Beth de Araújo, Marina Stabile, Channing Tatum, Gemma Chan, Mark H. Rapaport, Josh Beirne-Golden, Crystine Zhang | T23: Greta Zozula | U23: Anisha Acharya | V23: Miles Ross | W23: Mason Reeves, Channing Tatum, Gemma Chan, Philip Ettinger, Syra Mccarthy, Nico Leunen, Kyle Reiter | X23: Aos oito anos, Josephine testemunha uma violência sexual no Golden Gate Park, em San Francisco. A experiência abala profundamente sua sensação de segurança e a mergulha no medo e na paranoia. Sem conseguir elaborar o trauma, ela passa a reagir com violência, numa tentativa de recuperar o controle. Seus pais procuram ajudá-la, mas também precisam lidar com os próprios temores e divergências. Inspirado em uma experiência da infância da diretora Beth de Araújo. Vencedor do Grande Prêmio do Júri e do Prêmio do Público em Sundance 2026. | Y23: Direção: Beth de Araújo | Roteiro: Beth de Araújo | Produtora: Kaplan Morrison, Yintai Entertainment, Free Association, Spark Features | Produção: David Kaplan, Josh Peters, Beth de Araújo, Marina Stabile, Channing Tatum, Gemma Chan, Mark H. Rapaport, Josh Beirne-Golden, Crystine Zhang | Fotografia: Greta Zozula | Montagem: Anisha Acharya | Música: Miles Ross | Elenco: Mason Reeves, Channing Tatum, Gemma Chan, Philip Ettinger, Syra Mccarthy, Nico Leunen, Kyle Reiter | Z23: 3 | AA23: 2026 | AB23: Ficção
A24: 023 | B24: Panorama Mundial | C24: https://boxd.it/UEAa | D24: Monstro Gentil | E24: Gentle Monster | F24: Catálogo | G24: Alemanha + 2 países | H24: Ficção | I24: 115 | J24: 2026 | K24: Alemanha, França, Áustria | L24: Ficção | M24: Sim | N24: Cannes | O24: Competição Oficial | P24: Marie Kreutzer | Q24: Marie Kreutzer | R24: Film Ag | S24: Alexander Glehr, Johanna Scherz | T24: Judith Kaufmann | U24: Ulrike Kofler | V24: Camille | W24: Léa Seydoux, Laurence Rupp, Jella Haase, Malo Blanchet, Anton Rubtsov, Nils Strunk, Catherine Deneuve | X24: A pianista Lucy muda-se para o campo com o marido, Philip, e o filho pequeno deles, deixando a carreira em segundo plano para ajudar o parceiro a se recuperar de um esgotamento. Mas uma visita súbita da polícia ao amanhecer de um dia comum revela um segredo devastador e desestrutura a família. Enquanto Lucy busca a verdade e tenta proteger o filho, a agente-investigadora Elsa enfrenta revelações perturbadoras em sua própria vida pessoal. Estreia mundial na competição do Festival de Cannes 2026. | Y24: Direção: Marie Kreutzer | Roteiro: Marie Kreutzer | Produtora: Film Ag | Produção: Alexander Glehr, Johanna Scherz | Fotografia: Judith Kaufmann | Montagem: Ulrike Kofler | Música: Camille | Elenco: Léa Seydoux, Laurence Rupp, Jella Haase, Malo Blanchet, Anton Rubtsov, Nils Strunk, Catherine Deneuve | Z24: 3 | AA24: 2026 | AB24: Ficção
A25: 024 | B25: Panorama Mundial | C25: https://boxd.it/Lc9s | D25: No Good Men | E25: Kabul Jan | F25: Catálogo | G25: Alemanha + 4 países | H25: Ficção | I25: 104 | J25: 2026 | K25: Alemanha, França, Noruega, Dinamarca, Afeganistão | L25: Ficção | P25: Shahrbanoo Sadat | Q25: Shahrbanoo Sadat | R25: Amerikafilm, Wolf Pictures, Motlys, La Fabrica Nocturna Cinéma, Adomeit Film (Dk), Adomeit Film (D) | S25: Katja Adomeit, Shahrbanoo Sadat, Jeep Wowk, Marina Perales Marhuenda, Xavier Rocher, Ingvil Sæther Berger, Balthasar Busmann, Maxi Haslberger | T25: Virginie Surdej | U25: Alexandra Strauss | V25: Harpheet Bansal, Therese Aune, Kristian Eidnes Andersen | W25: Shahrbanoo Sadat, Anwar Hashimi, Liam Hussaini, Yasin Negah, Ahmad Azizi, Fatima Hassani, Masihullah Tajzai | X25: Afeganistão, 2021, pouco antes do retorno do Talibã ao poder. Naru, a única cinegrafista da principal emissora de TV de Cabul, luta para manter a guarda do filho de três anos. Após deixar o marido infiel, ela se convence de que não existem homens bons no país. Naru é pega de surpresa quando Qodrat, o jornalista mais importante da TV, lhe oferece uma oportunidade de carreira. Ao cobrirem os últimos dias de liberdade da cidade, surge uma faísca entre eles. Exibido na Berlinale Special Gala 2026. | Y25: Direção: Shahrbanoo Sadat | Roteiro: Shahrbanoo Sadat | Produtora: Amerikafilm, Wolf Pictures, Motlys, La Fabrica Nocturna Cinéma, Adomeit Film (Dk), Adomeit Film (D) | Produção: Katja Adomeit, Shahrbanoo Sadat, Jeep Wowk, Marina Perales Marhuenda, Xavier Rocher, Ingvil Sæther Berger, Balthasar Busmann, Maxi Haslberger | Fotografia: Virginie Surdej | Montagem: Alexandra Strauss | Música: Harpheet Bansal, Therese Aune, Kristian Eidnes Andersen | Elenco: Shahrbanoo Sadat, Anwar Hashimi, Liam Hussaini, Yasin Negah, Ahmad Azizi, Fatima Hassani, Masihullah Tajzai | Z25: 5 | AA25: 2026 | AB25: Ficção
A26: 025 | B26: Panorama Mundial | C26: https://boxd.it/XZ0I | D26: Nós Somos os Frutos da Floresta | E26: Nous sommes les fruits de la forêt | F26: Catálogo | G26: Camboja + 1 país | H26: Documentário | I26: 87 | J26: 2025 | K26: Camboja, França | L26: Documentário | P26: Rithy Panh | Q26: Rithy Panh | R26: Catherine Dussart Productions (Cdp) | S26: Catherine Dussart, Quentin François | T26: Prum Mésar, Mourng Vet, Cheng Socheat, Sok Chan Rado, Rithy Panh | U26: Rithy Panh, Eang Pisith | V26: Marc Mader | W26: Pa Kreb, Mak Kreb, Mak Lisa, Pouk Choeut, Mak Choeut, Yeay Kreb, Pouk Pritch, Mak Pritch, Pouk Vath, Pouk Loun, Lisa Choeut, Noas Pritch Kreb | X26: Filmado ao longo de quatro anos o documentário foca em algumas famílias da minoria étnica Bunong, que vive nas montanhas do nordeste do Camboja. Eles sobrevivem graças à terra e a práticas ancestrais, guiando-se pelos ciclos da floresta, que estão sendo severamente afetados por alterações nas estações do ano. Vencedor do Prêmio Especial do Júri no Festival Internacional de Cinema de Tóquio 2025. | Y26: Direção: Rithy Panh | Roteiro: Rithy Panh | Produtora: Catherine Dussart Productions (Cdp) | Produção: Catherine Dussart, Quentin François | Fotografia: Prum Mésar, Mourng Vet, Cheng Socheat, Sok Chan Rado, Rithy Panh | Montagem: Rithy Panh, Eang Pisith | Música: Marc Mader | Elenco: Pa Kreb, Mak Kreb, Mak Lisa, Pouk Choeut, Mak Choeut, Yeay Kreb, Pouk Pritch, Mak Pritch, Pouk Vath, Pouk Loun, Lisa Choeut, Noas Pritch Kreb | Z26: 3 | AA26: 2025 | AB26: Documentário
A27: 026 | B27: Panorama Mundial | C27: https://boxd.it/V6FC | D27: O Cheiro das Maçãs | E27: Reuk van Appels, Die | F27: Catálogo | G27: África do Sul + 2 países | H27: Ficção | I27: 104 | J27: 2026 | K27: Chile, Países Baixos, África do Sul | L27: Ficção | P27: John Trengove | Q27: John Trengove, Chris Ciancimino | R27: Portobello Productions, Cadence, Baldr Film, Quijote Films | S27: Eric Abraham, Jack Sidey, Cait Pansegrouw, Frank Hoeve | T27: Lennert Hillege, Nsc | U27: Matthew Swanepoel | W27: Dawian van Der Westhuizen, Hilton Pelser, Maude Sandham, Celeste Matthews Wan- Nenburgh, Alejandro Goic | X27: Na África do Sul de 1974, em pleno apartheid, Marnus, de 11 anos, leva uma vida protegida no universo privilegiado de sua família branca. Durante as férias de verão, uma acusação aparentemente banal desencadeia acontecimentos que abalam a imagem idealizada de seu pai e expõem a violência sob a fachada de normalidade. Adaptado do romance de Mark Behr, o drama acompanha o despertar doloroso de um menino para as contradições do mundo que o formou. Estreia mundial na competição Platform do Festival de Toronto 2026. | Y27: Direção: John Trengove | Roteiro: John Trengove, Chris Ciancimino | Produtora: Portobello Productions, Cadence, Baldr Film, Quijote Films | Produção: Eric Abraham, Jack Sidey, Cait Pansegrouw, Frank Hoeve | Fotografia: Lennert Hillege, Nsc | Montagem: Matthew Swanepoel | Elenco: Dawian van Der Westhuizen, Hilton Pelser, Maude Sandham, Celeste Matthews Wan- Nenburgh, Alejandro Goic | Z27: 3 | AA27: 2026 | AB27: Ficção
A28: 027 | B28: Panorama Mundial | C28: https://boxd.it/UlXY | D28: O Objeto do Delito | E28: L’objet du délit | F28: Catálogo | G28: França + 1 país | H28: Ficção | I28: 134 | J28: 2026 | K28: Bélgica, França | L28: Ficção | P28: Agnès Jaoui | Q28: Agnès Jaqui, Emmanuel Salinger, Laurent Jaqui, Noé Debré, Florence Seyvos | R28: Les Films du Kiosque | S28: François Kraus, Denis Pineau-Valencienne | T28: David Chizallet | U28: Christel Dewynter | V28: Fernando Fiszbein | W28: Eye Haidara, Claire Chust, Oussama Kheddam, Lucie Gallo, Tiphaine Daviot, Maxime Pambet, Loie Legendre, Vicenzo Amato | X28: Nos bastidores de uma ambiciosa produção da ópera As Bodas de Fígaro, as tensões aumentam quando surge uma acusação de agressão sexual, colocando em risco a produção e forçando todos a tomarem uma posição. | Y28: Direção: Agnès Jaoui | Roteiro: Agnès Jaqui, Emmanuel Salinger, Laurent Jaqui, Noé Debré, Florence Seyvos | Produtora: Les Films du Kiosque | Produção: François Kraus, Denis Pineau-Valencienne | Fotografia: David Chizallet | Montagem: Christel Dewynter | Música: Fernando Fiszbein | Elenco: Eye Haidara, Claire Chust, Oussama Kheddam, Lucie Gallo, Tiphaine Daviot, Maxime Pambet, Loie Legendre, Vicenzo Amato | Z28: 3 | AA28: 2026 | AB28: Ficção
A29: 028 | B29: Panorama Mundial | C29: https://boxd.it/AWo2 | D29: O Rebelde | E29: Uprising, The | F29: Catálogo | G29: Reino Unido + 2 países | H29: Ficção | I29: 127 | J29: 2026 | K29: Alemanha, Reino Unido, Estados Unidos | L29: Ficção | P29: Paul Greengrass | Q29: Paul Greengrass | R29: Electric Shadow Company, Blumhouse Productions, Atomic Monster, Thank You Pictures, Supernix, Filmnation Entertainment | S29: Jason Blum, Gregory Goodman, Paul Greengrass, Joanna Kaye, Joe Neurauter, Lars Sylvest | T29: Pål Ulvik Rokseth | U29: William Goldenberg | V29: Volker Bertelmann | W29: Andrew Garfield, Woody Norman, Katherine Waterson, Mark Redhead, Tom Hollander, Stephen Dillane, Stanley Townsend, Dónal Finn | X29: Inglaterra, 1381. Após a Peste Negra, a população enfrenta a fome, os impostos abusivos e a violência da Coroa. Devastado por uma perda pessoal, um humilde camponês se une à revolta contra o rei Ricardo II e acaba se tornando um de seus líderes. À frente de um exército popular, ele parte rumo a Londres em uma luta por justiça e sobrevivência que acabaria por inspirar a lenda de Robin Hood. | Y29: Direção: Paul Greengrass | Roteiro: Paul Greengrass | Produtora: Electric Shadow Company, Blumhouse Productions, Atomic Monster, Thank You Pictures, Supernix, Filmnation Entertainment | Produção: Jason Blum, Gregory Goodman, Paul Greengrass, Joanna Kaye, Joe Neurauter, Lars Sylvest | Fotografia: Pål Ulvik Rokseth | Montagem: William Goldenberg | Música: Volker Bertelmann | Elenco: Andrew Garfield, Woody Norman, Katherine Waterson, Mark Redhead, Tom Hollander, Stephen Dillane, Stanley Townsend, Dónal Finn | Z29: 3 | AA29: 2026 | AB29: Ficção
A30: 029 | B30: Panorama Mundial | C30: https://letterboxd.com/film/the-assassins-2026/ | D30: O(s) Assassino(s) | E30: Assassins, The | F30: Catálogo | G30: Coreia do Sul | H30: Ficção | I30: 131 | J30: 2026 | K30: Coreia do Sul | L30: Ficção | P30: Hur Jin-Ho | Q30: Gwon Gi-Jun, Lee Ji-Min | R30: Hive Media Corp. | S30: Kim Won-Kuk | T30: Lee Mo-Gae | U30: Kim Hana, Kim Woo-Hyun | V30: Cho Young-Wuk | W30: Yoo Hai-Jin, Park Hae-Il, Lee Min-Ho | X30: Coreia do Sul, 15 de agosto de 1974. Durante uma cerimônia transmitida ao vivo, tiros são disparados contra o presidente Park Chung-hee. Ele sobrevive, mas a primeira-dama Yuk Young-soo e uma menina são mortas. Quando duas balas desaparecem dos registros oficiais, um inspetor que testemunhou o atentado, um editor de jornal veterano e um repórter iniciante conduzem investigações paralelas. Entre censura, ameaças e interesses ocultos, os três desafiam uma engrenagem determinada a enterrar a verdade. Estreia mundial no Festival de Toronto 2026. | Y30: Direção: Hur Jin-Ho | Roteiro: Gwon Gi-Jun, Lee Ji-Min | Produtora: Hive Media Corp. | Produção: Kim Won-Kuk | Fotografia: Lee Mo-Gae | Montagem: Kim Hana, Kim Woo-Hyun | Música: Cho Young-Wuk | Elenco: Yoo Hai-Jin, Park Hae-Il, Lee Min-Ho | Z30: 3 | AA30: 2026 | AB30: Ficção
A31: 030 | B31: Panorama Mundial | C31: https://letterboxd.com/film/the-last-resort-2026/ | D31: O Último Resort | E31: Paradis | F31: Catálogo | G31: Dinamarca + 1 país | H31: Ficção | I31: 98 | J31: 2026 | K31: Dinamarca, Noruega | L31: Ficção | P31: Maria Sødahl | Q31: Maria Sødahl, Therese Hasman, Eske Troelstrup | R31: Nordisk Film Production | S31: Thomas Robsahm, Sigurd Mikal Karoliussen | T31: John-Erling Holmenes Fredriksen | U31: Kristofer Nordin | V31: Martin Juel Dirkov | W31: Danica Curcic, Esben Smed, Aziz Çapkurt, Sif Lucca Gersby, Chili Olivia Jensen, Claes Ljungmark, Per Kjerstad, Marte Engebrigtsen, Petrine Agger, Nanna Finding Koppel | X31: Mikkel e Louise viajam com as duas filhas para férias num resort com tudo incluído em Gran Canaria. O descanso termina quando atropelam acidentalmente um homem que, mais tarde, aparece no hotel pedindo ajuda. Convencido de que deve fazer o que é certo, o casal aceita o pedido. Mas, à medida que se envolve, seus valores são postos à prova, e a família precisa confrontar o que significa ser uma boa pessoa — e quanto está disposta a arriscar por alguém em necessidade. Vencedor do Dragon Award de melhor filme nórdico no Festival de Gotemburgo 2026. | Y31: Direção: Maria Sødahl | Roteiro: Maria Sødahl, Therese Hasman, Eske Troelstrup | Produtora: Nordisk Film Production | Produção: Thomas Robsahm, Sigurd Mikal Karoliussen | Fotografia: John-Erling Holmenes Fredriksen | Montagem: Kristofer Nordin | Música: Martin Juel Dirkov | Elenco: Danica Curcic, Esben Smed, Aziz Çapkurt, Sif Lucca Gersby, Chili Olivia Jensen, Claes Ljungmark, Per Kjerstad, Marte Engebrigtsen, Petrine Agger, Nanna Finding Koppel | Z31: 3 | AA31: 2026 | AB31: Ficção
A32: 031 | B32: Panorama Mundial | C32: https://letterboxd.com/film/eight-bridges/ | D32: Oito Pontes | E32: Eight Bridges | F32: Catálogo | G32: Estados Unidos | H32: Ficção | I32: 82 | J32: 2026 | K32: Estados Unidos | L32: Ficção | P32: James Benning | X32: Em oito planos fixos de dez minutos, James Benning contempla pontes dos Estados Unidos, indo da Golden Gate, em São Francisco, à histórica Edmund Pettus, em Selma. No encontro entre terra, água e céu, essas estruturas conectam os mundos construído e natural, conduzindo fluxos de pessoas, capital e história. Sem diálogos, este ensaio visual meditativo transforma a observação paciente em uma reflexão sobre os Estados Unidos, a percepção e o tempo. Estreia mundial no Fórum do Festival de Berlim 2026. | Y32: Direção: James Benning | Z32: 3 | AA32: 2026 | AB32: Ficção
A33: 032 | B33: Panorama Mundial | C33: https://letterboxd.com/film/growth-of-the-soil-2026/ | D33: Os Frutos da Terra | E33: Markens grøde | F33: Catálogo | G33: Noruega | H33: Ficção | I33: 155 | J33: 2026 | K33: Noruega | L33: Ficção | P33: Hans Petter Moland | Q33: Hans Petter Moland, Gard B. Eidsvold | R33: Scanbox Entertainment, 4 1/2 Fiction as | S33: Håkon Øverås | T33: Oskar Dahlsbakken | U33: Linda Man | V33: Kaspar Kaae | W33: Herbert Nordrum, Asta Kamma August, Gard B Eidsvold, Anders Baasmo | X33: Umm homem e uma mulher enfrentam a imensidão da natureza, abrindo caminhos nos arredores isolados do norte da Noruega. Guiados pelas necessidades elementares da vida, suas habilidades e resistência são postas à prova à medida que grandes desafios se aproximam. Baseado no romance que deu o Prêmio Nobel de Literatura a Knut Hamsun, este drama retrata com fidelidade a força da terra e os limites da sobrevivência. Exibido no Toronto International Film Festival 2026 na mostra Special Presentations. | Y33: Direção: Hans Petter Moland | Roteiro: Hans Petter Moland, Gard B. Eidsvold | Produtora: Scanbox Entertainment, 4 1/2 Fiction as | Produção: Håkon Øverås | Fotografia: Oskar Dahlsbakken | Montagem: Linda Man | Música: Kaspar Kaae | Elenco: Herbert Nordrum, Asta Kamma August, Gard B Eidsvold, Anders Baasmo | Z33: 3 | AA33: 2026 | AB33: Ficção
A34: 033 | B34: Panorama Mundial | C34: https://letterboxd.com/film/prima-facie-2026/ | D34: Prima Facie | F34: Complementar / catálogo parcial | G34: Austrália + 1 país | H34: Ficção | I34: 106 | J34: 2026 | K34: Austrália, Reino Unido | L34: Ficção | P34: Susanna White | Q34: Suzie Miller | R34: Camelback Productions, Minderoo Pictures, Edith's Daughter, Embankment Films, Bunya Productions | S34: Greer Simpkin, Kevin Loader, David Jowsey | T34: Mike Eley | U34: Justine Wright | V34: Isobel Waller-Bridge | W34: Cynthia Erivo, Daniel Ings, Noma Dumezweni, Elizabeth Dulau, Toheeb Jimoh, Harry Treadaway, Khalid Abdalla, Elliot Levey, Simon Russell-Beale, Sarah Junillon | X34: A indicada ao Oscar Cynthia Erivo (Wicked) estrela esta adaptação da peça de Suzie Miller. A trama examina o que acontece quando uma advogada ambiciosa, que defende principalmente acusados de crimes sexuais, inesperadamente se torna a denunciante em um caso de agressão sexual. Forçada a ir ao banco das testemunhas, ela deve enfrentar o mesmo sistema jurídico em que confiava, confrontando as duras realidades da justiça e do poder pelo outro lado. | Y34: Direção: Susanna White | Roteiro: Suzie Miller | Produtora: Camelback Productions, Minderoo Pictures, Edith's Daughter, Embankment Films, Bunya Productions | Produção: Greer Simpkin, Kevin Loader, David Jowsey | Fotografia: Mike Eley | Montagem: Justine Wright | Música: Isobel Waller-Bridge | Elenco: Cynthia Erivo, Daniel Ings, Noma Dumezweni, Elizabeth Dulau, Toheeb Jimoh, Harry Treadaway, Khalid Abdalla, Elliot Levey, Simon Russell-Beale, Sarah Junillon | Z34: 3 | AA34: 2026 | AB34: Ficção
A35: 034 | B35: Panorama Mundial | C35: https://letterboxd.com/film/four-minus-three/ | D35: Quatro Menos Três | E35: Vier Minus Drei | F35: Catálogo | G35: Áustria + 1 país | H35: Ficção | I35: 121 | J35: 2025 | K35: Áustria, Alemanha | L35: Ficção | P35: Adrian Goiginger | Q35: Senad Halilbašić | R35: Giganten Film Produktions Gmbh, 2010 Entertainment Gmbh | S35: Peter Wildling, Gerrit Klein, Martin Pfeil, David Stöllinger, Adrian Goiginger | T35: Paul Sprinz | U35: Martin Pfeil, Simon Blasi | V35: Arash Safaian | W35: Valerie Pachner, Robert Stadlober, Stefanie Reinsperger, Hanno Koffler, Margarethe Tiesel, Paul Wolff-Plottegg, Michael Gampe, Ronald Zehrfeld, Michael Fuith, Wolfgang Lampl, Sophia Laggner, Petra Morzé | X35: Barbara, uma animadora profissional, vê seu mundo desmoronar após uma perda familiar devastadora. Como única sobrevivente de uma tragédia, ela enfrenta o doloroso processo de luto e isolamento. Este drama sensível explora as profundezas da dor humana e o difícil desafio de reconstruir a vida do zero. Baseado em uma emocionante história real, o filme foca na busca por um novo sentido e na resiliência necessária para reencontrar a esperança quando tudo parece perdido. Exibido na Mostra Panorama do Festival de Berlim 2026. | Y35: Direção: Adrian Goiginger | Roteiro: Senad Halilbašić | Produtora: Giganten Film Produktions Gmbh, 2010 Entertainment Gmbh | Produção: Peter Wildling, Gerrit Klein, Martin Pfeil, David Stöllinger, Adrian Goiginger | Fotografia: Paul Sprinz | Montagem: Martin Pfeil, Simon Blasi | Música: Arash Safaian | Elenco: Valerie Pachner, Robert Stadlober, Stefanie Reinsperger, Hanno Koffler, Margarethe Tiesel, Paul Wolff-Plottegg, Michael Gampe, Ronald Zehrfeld, Michael Fuith, Wolfgang Lampl, Sophia Laggner, Petra Morzé | Z35: 3 | AA35: 2025 | AB35: Ficção
A36: 035 | B36: Panorama Mundial | C36: https://letterboxd.com/film/queen-at-sea/ | D36: Rainha ao Mar | E36: Queen At Sea | F36: Catálogo | G36: Estados Unidos + 1 país | H36: Ficção | I36: 121 | J36: 2026 | K36: Estados Unidos, Reino Unido | L36: Ficção | M36: Sim | N36: Berlinale | O36: Competição Oficial | P36: Lance Hammer | Q36: Lance Hammer | R36: Alluvial Film Company, The Bureau | S36: Tristan Goligher, Lance Hammer | T36: Adolpho Veloso | U36: Lance Hammer | V36: Georgiamae Bromley, Connie Farr | W36: Juliette Binoche, Tom Courtenay, Anna Calder-Marshall, Florence Hunt | X36: À medida que a demência avançada compromete a capacidade de Leslie expressar seus desejos, sua filha Amanda e seu marido, Martin, entram em conflito sobre quem deve decidir o que é melhor para ela. As tentativas de equilibrar amor, proteção e autonomia levam a escolhas cada vez mais difíceis, com consequências que escapam ao controle de todos. Vencedor do Prêmio do Júri e de Melhor Atriz Coadjuvante para Anna Calder-Marshall no Festival de Berlim 2026. | Y36: Direção: Lance Hammer | Roteiro: Lance Hammer | Produtora: Alluvial Film Company, The Bureau | Produção: Tristan Goligher, Lance Hammer | Fotografia: Adolpho Veloso | Montagem: Lance Hammer | Música: Georgiamae Bromley, Connie Farr | Elenco: Juliette Binoche, Tom Courtenay, Anna Calder-Marshall, Florence Hunt | Z36: 3 | AA36: 2026 | AB36: Ficção
A37: 036 | B37: Panorama Mundial | C37: https://letterboxd.com/film/rose-2026/ | D37: Rose | F37: Complementar / catálogo parcial | G37: Áustria + 1 país | H37: Ficção | I37: 93 | J37: 2026 | K37: Áustria, Alemanha | L37: Ficção | M37: Sim | N37: Berlinale | O37: Competição Oficial | P37: Markus Schleinzer | Q37: Markus Schleinzer, Alexander Born | S37: Johannes Schubert, Philipp Worm, Tobias Walker, Karsten Stöter | T37: Gerald Kerkletz | U37: Hansjörg Weissbrich | V37: Tara Nome Doyle | W37: Sandra Hüller, Caro Braun, Marissa Growaldt, Robert Gwisdek, Godehard Giese | X37: No início do século XVII, em meio à devastação da Guerra dos Trinta Anos, um misterioso soldado chega a um isolado vilarejo protestante na Alemanha, afirmando ser o herdeiro de uma propriedade abandonada. Embora aos poucos vá conquistando a confiança dos moradores, as suspeitas sobre sua identidade nunca deixam de existir, e ameaçam destruir a vida construída sobre uma farsa impossível. Estreia mundial na competição do Festival de Berlim 2026, em que Sandra Hüller recebeu o Urso de Prata de Melhor Atriz. | Y37: Direção: Markus Schleinzer | Roteiro: Markus Schleinzer, Alexander Born | Produção: Johannes Schubert, Philipp Worm, Tobias Walker, Karsten Stöter | Fotografia: Gerald Kerkletz | Montagem: Hansjörg Weissbrich | Música: Tara Nome Doyle | Elenco: Sandra Hüller, Caro Braun, Marissa Growaldt, Robert Gwisdek, Godehard Giese | Z37: 4 | AA37: 2026 | AB37: Ficção
A38: 037 | B38: Panorama Mundial | C38: https://letterboxd.com/film/rosebush-pruning/ | D38: Rosebush Pruning | F38: Complementar / catálogo parcial | G38: Itália + 3 países | H38: Ficção | I38: 97 | J38: 2026 | K38: Itália, Alemanha, Espanha, Reino Unido | L38: Ficção | P38: Karim Aïnouz | Q38: Efthimis Filippou | R38: The Match Factory, Kavac Film, The Apartment (a Freemantle Company), Sur Film, Rosebushpruning, Crybaby | S38: Viola Fügen, Michael Weber | T38: Hélène Louvart | U38: Heike Parpi, David Jancso, Ilka Janka Nagy | V38: Matthew Herbert | W38: Callun Turner, Elena Anaya, Elle Fanning, Jamie Bell, Lukas Gage, Pamela Anderson, Riley Keough, Tracy Letts | X38: Sob o sol da Catalunha, quatro irmãos norte-americanos vivem com o pai cego em uma mansão, entregues ao isolamento, à fortuna herdada, às roupas de grife e a uma relação de dependência mútua. Quando Jack, o irmão mais velho e pilar da família, anuncia que vai morar com a namorada Martha, o frágil equilíbrio começa a ruir. À medida que Ed investiga a verdade sobre a morte da mãe, antigos segredos e mentiras vêm à tona, desintegrando os laços familiares. Estreia mundial na Competição Oficial do Festival de Berlim 2026. | Y38: Direção: Karim Aïnouz | Roteiro: Efthimis Filippou | Produtora: The Match Factory, Kavac Film, The Apartment (a Freemantle Company), Sur Film, Rosebushpruning, Crybaby | Produção: Viola Fügen, Michael Weber | Fotografia: Hélène Louvart | Montagem: Heike Parpi, David Jancso, Ilka Janka Nagy | Música: Matthew Herbert | Elenco: Callun Turner, Elena Anaya, Elle Fanning, Jamie Bell, Lukas Gage, Pamela Anderson, Riley Keough, Tracy Letts | Z38: 4 | AA38: 2026 | AB38: Ficção
A39: 038 | B39: Panorama Mundial | C39: https://letterboxd.com/film/no-pain-2026/ | D39: Sem Dor | E39: Nessun dolore | F39: Catálogo | G39: Itália | H39: Ficção | I39: 96 | J39: 2026 | K39: Itália | L39: Ficção | M39: Sim | N39: Veneza | O39: Venice Open – Fora de Competição | P39: Gianni Amelio | Q39: Gianni Amelio, Davide Serino, Andrea Quetti | R39: Kavac Film, Our Films, Be Water Film | S39: Simone Gattoni, Marco Bellocchio, Lorenzo Mieli, Mario Gianani, Mattia Guerra | T39: Luan Amelio Ujkaj | U39: Stefano Mariotti | V39: Fabio Massimo Capogrosso | W39: Alessandro Borghi, Valeria Golino, Valerio Mastandrea, Beidja Yahiaoui, Ramzi Lafrindi, Gabriel Bovino | X39: Davide, um livreiro de trinta e poucos anos, vende livros usados numa praça de Roma e leva uma vida solitária, tendo como principal companhia Elsa, professora de literatura com quem mantém uma relação de amizade e afeto. Tudo muda quando um desconhecido deixa sob seus cuidados um menino norte-africano. Após um acidente que o enche de culpa, Davide acolhe Aminah, uma adolescente argelina grávida e sem ter para onde ir. Aos poucos, sua casa se transforma em abrigo para migrantes. Exibido fora de competição no Festival de Veneza 2026. | Y39: Direção: Gianni Amelio | Roteiro: Gianni Amelio, Davide Serino, Andrea Quetti | Produtora: Kavac Film, Our Films, Be Water Film | Produção: Simone Gattoni, Marco Bellocchio, Lorenzo Mieli, Mario Gianani, Mattia Guerra | Fotografia: Luan Amelio Ujkaj | Montagem: Stefano Mariotti | Música: Fabio Massimo Capogrosso | Elenco: Alessandro Borghi, Valeria Golino, Valerio Mastandrea, Beidja Yahiaoui, Ramzi Lafrindi, Gabriel Bovino | Z39: 3 | AA39: 2026 | AB39: Ficção
A40: 039 | B40: Panorama Mundial | C40: https://letterboxd.com/film/well-find-happiness/ | D40: Seremos Felizes | E40: On Seura Heureux | F40: Catálogo | G40: Canadá + 1 país | H40: Ficção | I40: 101 | J40: 2025 | K40: Canadá, Luxemburgo | L40: Ficção | P40: Lea Pool | Q40: Michel Marc Bouchard | S40: Lyse Lafontaine, Katarzyna Ozg | T40: Yves Bélanger | U40: Michel Arcand | V40: Kyan Bayani | W40: Mehdi Meskar, Alexandre Landry, Aron Archer, Céline Bonnier, Sascha Ley | X40: Saad, um refugiado marroquino, vive no Canadá com Reza, seu companheiro iraniano. Quando Reza enfrenta a ameaça de deportação para um país onde sua vida corre perigo, o casal inicia uma corrida contra o tempo. Diante do rigoroso sistema de imigração, Saad arrisca tudo em um plano desesperado para salvar o homem que ama, testando os limites do afeto e da sobrevivência. | Y40: Direção: Lea Pool | Roteiro: Michel Marc Bouchard | Produção: Lyse Lafontaine, Katarzyna Ozg | Fotografia: Yves Bélanger | Montagem: Michel Arcand | Música: Kyan Bayani | Elenco: Mehdi Meskar, Alexandre Landry, Aron Archer, Céline Bonnier, Sascha Ley | Z40: 4 | AA40: 2025 | AB40: Ficção
...

Sheet Sessões
A1: Data | B1: Dia | C1: Horário | D1: Mostra | E1: ID | F1: Filme | G1: Cinema | H1: Endereço | I1: Sala | J1: Observações | K1: Gratuita | L1: Com convidado | M1: Com debate
A2: 46301 | B2: Ter | C2: 0.8125 | D2: Panorama Mundial | E2: {=_xlfn.XLOOKUP(F2, Filmes!$D$2:$D$344, Filmes!$A$2:$A$344, "")} -> 001 | F2: A Grande Estreia | G2: Cine Odeon - CCLSR | H2: Praça Floriano, 7
